<?xml version="1.0" encoding="UTF-8"?>
<!-- Generated by org.testng.reporters.JUnitReportReporter -->
<testsuite skipped="3" hostname="DESKTOP-0AG0V8V" name="com.RetryFailedTestsWithTestNGAtSuitLevel.SampleTest" tests="5" failures="1" timestamp="28 Oct 2019 20:03:33 GMT" time="0.037" errors="0">
  <testcase name="test1" time="0.003" classname="com.RetryFailedTestsWithTestNGAtSuitLevel.SampleTest">
    <skipped/>
  </testcase> <!-- test1 -->
  <testcase name="test1" time="0.003" classname="com.RetryFailedTestsWithTestNGAtSuitLevel.SampleTest">
    <skipped/>
  </testcase> <!-- test1 -->
  <testcase name="test1" time="0.027" classname="com.RetryFailedTestsWithTestNGAtSuitLevel.SampleTest">
    <skipped/>
  </testcase> <!-- test1 -->
  <testcase name="test1" time="0.002" classname="com.RetryFailedTestsWithTestNGAtSuitLevel.SampleTest">
    <failure type="java.lang.AssertionError" message="Addition Problem! 2+2 must be 4!
 expected [5] but found [4]">
      <![CDATA[java.lang.AssertionError: Addition Problem! 2+2 must be 4!
 expected [5] but found [4]
at org.testng.Assert.fail(Assert.java:96)
at org.testng.Assert.failNotEquals(Assert.java:776)
at org.testng.Assert.assertEqualsImpl(Assert.java:137)
at org.testng.Assert.assertEquals(Assert.java:118)
at org.testng.Assert.assertEquals(Assert.java:652)
at com.RetryFailedTestsWithTestNGAtSuitLevel.SampleTest.test1(SampleTest.java:11)
at sun.reflect.NativeMethodAccessorImpl.invoke0(Native Method)
at sun.reflect.NativeMethodAccessorImpl.invoke(NativeMethodAccessorImpl.java:62)
at sun.reflect.DelegatingMethodAccessorImpl.invoke(DelegatingMethodAccessorImpl.java:43)
at java.lang.reflect.Method.invoke(Method.java:498)
at org.testng.internal.MethodInvocationHelper.invokeMethod(MethodInvocationHelper.java:124)
at org.testng.internal.Invoker.invokeMethod(Invoker.java:583)
at org.testng.internal.Invoker.retryFailed(Invoker.java:839)
at org.testng.internal.Invoker.invokeTestMethods(Invoker.java:1010)
at org.testng.internal.TestMethodWorker.invokeTestMethods(TestMethodWorker.java:125)
at org.testng.internal.TestMethodWorker.run(TestMethodWorker.java:109)
at org.testng.TestRunner.privateRun(TestRunner.java:648)
at org.testng.TestRunner.run(TestRunner.java:505)
at org.testng.SuiteRunner.runTest(SuiteRunner.java:455)
at org.testng.SuiteRunner.runSequentially(SuiteRunner.java:450)
at org.testng.SuiteRunner.privateRun(SuiteRunner.java:415)
at org.testng.SuiteRunner.run(SuiteRunner.java:364)
at org.testng.SuiteRunnerWorker.runSuite(SuiteRunnerWorker.java:52)
at org.testng.SuiteRunnerWorker.run(SuiteRunnerWorker.java:84)
at org.testng.TestNG.runSuitesSequentially(TestNG.java:1208)
at org.testng.TestNG.runSuitesLocally(TestNG.java:1137)
at org.testng.TestNG.runSuites(TestNG.java:1049)
at org.testng.TestNG.run(TestNG.java:1017)
at org.testng.remote.AbstractRemoteTestNG.run(AbstractRemoteTestNG.java:115)
at org.testng.remote.RemoteTestNG.initAndRun(RemoteTestNG.java:251)
at org.testng.remote.RemoteTestNG.main(RemoteTestNG.java:77)
]]>
    </failure>
  </testcase> <!-- test1 -->
  <testcase name="test2" time="0.002" classname="com.RetryFailedTestsWithTestNGAtSuitLevel.SampleTest"/>
</testsuite> <!-- com.RetryFailedTestsWithTestNGAtSuitLevel.SampleTest -->
